<?xml version="1.0"?>
<robot name="ti_rlsk_max" xmlns:xacro="http://www.ros.org/wiki/xacro">

  <!-- Definición de materiales -->

    <material name="black">
        <color rgba="0.0 0.0 0.0 1.0"/>
    </material>

    <material name="silver">
        <color rgba="0.8 0.8 0.8 1.0"/>
    </material>


    <link name="base_link">
        <!-- Propiedades inertiales y visuales de la base aquí -->
        ...
        <!-- Inserción del caster front como una sección de colisión y visual -->
        <collision name="caster_front_collision">
            <origin xyz="0.35 0 -0.05" rpy="0 0 0"/> <!-- Posición del caster respecto al centro de la base -->
            <geometry>
            <sphere radius="0.05"/> <!-- Tamaño del caster -->
            </geometry>
        </collision>

        <visual name="caster_front_visual">
            <origin xyz="0.35 0 -0.05" rpy="0 0 0"/> <!-- Asegúrate de que la posición coincida con la de collision -->
            <geometry>
            <sphere radius="0.05"/> <!-- Apariencia visual del caster -->
            </geometry>
            <material name="black"/> <!-- Material del caster -->
        </visual>
    </link>

  <!-- Rueda derecha -->
  <link name="right_wheel_link">
    <visual>
      <geometry>
        <cylinder radius="0.05" length="0.02"/> <!-- Rueda -->
      </geometry>
      <material name="black"/>
    </visual>
    <!-- Añadir elementos inertial y collision si es necesario -->
  </link>

  <!-- Rueda izquierda -->
  <link name="left_wheel_link">
    <visual>
      <geometry>
        <cylinder radius="0.05" length="0.02"/> <!-- Rueda -->
      </geometry>
      <material name="black"/>
    </visual>
    <!-- Añadir elementos inertial y collision si es necesario -->
  </link>
 

  <!-- Joint fijo para la base -->
  <!-- <joint name="base_joint" type="fixed">
    <parent link="world"/>
    <child link="base_link"/>
    <origin xyz="0 0 0" rpy="0 0 0"/>
  </joint> -->

  <!-- Joints para las ruedas -->
    <joint name="right_wheel_joint" type="continuous">
    <parent link="base_link"/>
    <child link="right_wheel_link"/>
    <origin xyz="0.15 0 -0.025" rpy="0 1.5708 0"/> <!-- Rueda girada 90 grados en pitch -->
    <axis xyz="0 0 1"/> <!-- Eje de rotación para la rueda derecha -->
    </joint>

    <joint name="left_wheel_joint" type="continuous">
    <parent link="base_link"/>
    <child link="left_wheel_link"/>
    <origin xyz="-0.15 0 -0.025" rpy="0 1.5708 0"/> <!-- Rueda girada 90 grados en pitch -->
    <axis xyz="0 0 1"/> <!-- Eje de rotación para la rueda izquierda -->
    </joint>
</robot>
